<?xml version="1.0" ?>
<!-- =================================================================================== -->
<!-- |    This document was autogenerated by xacro from /home/i/robot_realman/rmc_aida_l_ros1/src/robot_description/urdf/robots/embodied_dual_arms.urdf.xacro | -->
<!-- |    EDITING THIS FILE BY HAND IS NOT RECOMMENDED                                 | -->
<!-- =================================================================================== -->
<robot name="robot_description">
    <link name="base_link_underpan">
        <inertial>
            <origin rpy="0 0 0" xyz="-0.012628 -0.016092 -0.060646" />
            <mass value="2.5521" />
            <inertia ixx="0.066197" ixy="7.0297E-05" ixz="0.00017628" iyy="0.034903" iyz="-0.00059595" izz="0.097938" />
        </inertial>
        <visual>
            <origin rpy="0 0 0" xyz="0 0 0" />
            <geometry>
                <mesh filename="package://robot_description/meshes/common/base_link_underpan.STL" />
            </geometry>
            <material name="">
                <color rgba="0.79216 0.81961 0.93333 1" />
            </material>
        </visual>
        <collision>
            <origin rpy="0 0 0" xyz="0 0 0" />
            <geometry>
                <mesh filename="package://robot_description/meshes/common/base_link_underpan.STL" />
            </geometry>
        </collision>
    </link>
    <link name="link_right_wheel">
        <inertial>
            <origin rpy="0 0 0" xyz="-0.024898 2.5665E-18 0" />
            <mass value="1.0523" />
            <inertia ixx="0.0033125" ixy="1.5953E-19" ixz="1.2287E-20" iyy="0.0018066" iyz="2.5666E-19" izz="0.0018066" />
        </inertial>
        <visual>
            <origin rpy="0 0 0" xyz="0 0 0" />
            <geometry>
                <mesh filename="package://robot_description/meshes/common/link_right_wheel.STL" />
            </geometry>
            <material name="">
                <color rgba="0.79216 0.81961 0.93333 1" />
            </material>
        </visual>
        <collision>
            <origin rpy="0 0 0" xyz="0 0 0" />
            <geometry>
                <mesh filename="package://robot_description/meshes/common/link_right_wheel.STL" />
            </geometry>
        </collision>
    </link>
    <link name="link_left_wheel">
        <inertial>
            <origin rpy="0 0 0" xyz="0.025224 -8.8034E-15 0" />
            <mass value="1.0734" />
            <inertia ixx="0.0033996" ixy="-5.0277E-16" ixz="9.2981E-21" iyy="0.0019593" iyz="3.7534E-19" izz="0.0019593" />
        </inertial>
        <visual>
            <origin rpy="0 0 0" xyz="0 0 0" />
            <geometry>
                <mesh filename="package://robot_description/meshes/common/link_left_wheel.STL" />
            </geometry>
            <material name="">
                <color rgba="0.79216 0.81961 0.93333 1" />
            </material>
        </visual>
        <collision>
            <origin rpy="0 0 0" xyz="0 0 0" />
            <geometry>
                <mesh filename="package://robot_description/meshes/common/link_left_wheel.STL" />
            </geometry>
        </collision>
    </link>
    <link name="link_swivel_wheel_1_1">
        <inertial>
            <origin rpy="0 0 0" xyz="0.00067987 -0.0050012 -0.013414" />
            <mass value="0.088835" />
            <inertia ixx="3.1679E-05" ixy="2.0129E-08" ixz="2.7021E-08" iyy="3.9438E-05" iyz="-3.2776E-06" izz="4.6143E-05" />
        </inertial>
        <visual>
            <origin rpy="0 0 0" xyz="0 0 0" />
            <geometry>
                <mesh filename="package://robot_description/meshes/common/link_swivel_wheel_1_1.STL" />
            </geometry>
            <material name="">
                <color rgba="0.79216 0.81961 0.93333 1" />
            </material>
        </visual>
        <collision>
            <origin rpy="0 0 0" xyz="0 0 0" />
            <geometry>
                <mesh filename="package://robot_description/meshes/common/link_swivel_wheel_1_1.STL" />
            </geometry>
        </collision>
    </link>
    <link name="link_swivel_wheel_1_2">
        <inertial>
            <origin rpy="0 0 0" xyz="0.0010651 2.2204E-16 9.4369E-16" />
            <mass value="0.12664" />
            <inertia ixx="0.00011169" ixy="1.1345E-14" ixz="2.2064E-14" iyy="6.0838E-05" iyz="1.7051E-09" izz="6.084E-05" />
        </inertial>
        <visual>
            <origin rpy="0 0 0" xyz="0 0 0" />
            <geometry>
                <mesh filename="package://robot_description/meshes/common/link_swivel_wheel_1_2.STL" />
            </geometry>
            <material name="">
                <color rgba="0.79216 0.81961 0.93333 1" />
            </material>
        </visual>
        <collision>
            <origin rpy="0 0 0" xyz="0 0 0" />
            <geometry>
                <mesh filename="package://robot_description/meshes/common/link_swivel_wheel_1_2.STL" />
            </geometry>
        </collision>
    </link>
    <link name="link_swivel_wheel_2_1">
        <inertial>
            <origin rpy="0 0 0" xyz="0.00067987 -0.0050012 -0.013414" />
            <mass value="0.088835" />
            <inertia ixx="3.1679E-05" ixy="2.0129E-08" ixz="2.7021E-08" iyy="3.9438E-05" iyz="-3.2776E-06" izz="4.6143E-05" />
        </inertial>
        <visual>
            <origin rpy="0 0 0" xyz="0 0 0" />
            <geometry>
                <mesh filename="package://robot_description/meshes/common/link_swivel_wheel_2_1.STL" />
            </geometry>
            <material name="">
                <color rgba="0.79216 0.81961 0.93333 1" />
            </material>
        </visual>
        <collision>
            <origin rpy="0 0 0" xyz="0 0 0" />
            <geometry>
                <mesh filename="package://robot_description/meshes/common/link_swivel_wheel_2_1.STL" />
            </geometry>
        </collision>
    </link>
    <link name="link_swivel_wheel_2_2">
        <inertial>
            <origin rpy="0 0 0" xyz="0.0010651 6.1062E-16 7.7716E-16" />
            <mass value="0.12664" />
            <inertia ixx="0.00011169" ixy="1.9869E-14" ixz="1.4856E-14" iyy="6.084E-05" iyz="2.0109E-09" izz="6.0838E-05" />
        </inertial>
        <visual>
            <origin rpy="0 0 0" xyz="0 0 0" />
            <geometry>
                <mesh filename="package://robot_description/meshes/common/link_swivel_wheel_2_2.STL" />
            </geometry>
            <material name="">
                <color rgba="0.79216 0.81961 0.93333 1" />
            </material>
        </visual>
        <collision>
            <origin rpy="0 0 0" xyz="0 0 0" />
            <geometry>
                <mesh filename="package://robot_description/meshes/common/link_swivel_wheel_2_2.STL" />
            </geometry>
        </collision>
    </link>
    <link name="link_swivel_wheel_3_1">
        <inertial>
            <origin rpy="0 0 0" xyz="0.00067987 -0.0050012 -0.013414" />
            <mass value="0.088835" />
            <inertia ixx="3.1679E-05" ixy="2.0129E-08" ixz="2.7021E-08" iyy="3.9438E-05" iyz="-3.2776E-06" izz="4.6143E-05" />
        </inertial>
        <visual>
            <origin rpy="0 0 0" xyz="0 0 0" />
            <geometry>
                <mesh filename="package://robot_description/meshes/common/link_swivel_wheel_3_1.STL" />
            </geometry>
            <material name="">
                <color rgba="0.79216 0.81961 0.93333 1" />
            </material>
        </visual>
        <collision>
            <origin rpy="0 0 0" xyz="0 0 0" />
            <geometry>
                <mesh filename="package://robot_description/meshes/common/link_swivel_wheel_3_1.STL" />
            </geometry>
        </collision>
    </link>
    <link name="link_swivel_wheel_3_2">
        <inertial>
            <origin rpy="0 0 0" xyz="0.0010651 -3.3307E-16 8.8818E-16" />
            <mass value="0.12664" />
            <inertia ixx="0.00011169" ixy="-1.8513E-15" ixz="2.474E-14" iyy="6.0837E-05" iyz="-3.1204E-10" izz="6.0841E-05" />
        </inertial>
        <visual>
            <origin rpy="0 0 0" xyz="0 0 0" />
            <geometry>
                <mesh filename="package://robot_description/meshes/common/link_swivel_wheel_3_2.STL" />
            </geometry>
            <material name="">
                <color rgba="0.79216 0.81961 0.93333 1" />
            </material>
        </visual>
        <collision>
            <origin rpy="0 0 0" xyz="0 0 0" />
            <geometry>
                <mesh filename="package://robot_description/meshes/common/link_swivel_wheel_3_2.STL" />
            </geometry>
        </collision>
    </link>
    <link name="link_swivel_wheel_4_1">
        <inertial>
            <origin rpy="0 0 0" xyz="0.00067987 -0.0050012 -0.0094542" />
            <mass value="0.088835" />
            <inertia ixx="3.1679E-05" ixy="2.0129E-08" ixz="2.7021E-08" iyy="3.9438E-05" iyz="-3.2776E-06" izz="4.6143E-05" />
        </inertial>
        <visual>
            <origin rpy="0 0 0" xyz="0 0 0" />
            <geometry>
                <mesh filename="package://robot_description/meshes/common/link_swivel_wheel_4_1.STL" />
            </geometry>
            <material name="">
                <color rgba="0.79216 0.81961 0.93333 1" />
            </material>
        </visual>
        <collision>
            <origin rpy="0 0 0" xyz="0 0 0" />
            <geometry>
                <mesh filename="package://robot_description/meshes/common/link_swivel_wheel_4_1.STL" />
            </geometry>
        </collision>
    </link>
    <link name="link_swivel_wheel_4_2">
        <inertial>
            <origin rpy="0 0 0" xyz="0.0010651 -4.996E-16 7.494E-16" />
            <mass value="0.12664" />
            <inertia ixx="0.00011169" ixy="-7.4776E-15" ixz="2.3656E-14" iyy="6.0837E-05" iyz="-1.205E-09" izz="6.0841E-05" />
        </inertial>
        <visual>
            <origin rpy="0 0 0" xyz="0 0 0" />
            <geometry>
                <mesh filename="package://robot_description/meshes/common/link_swivel_wheel_4_2.STL" />
            </geometry>
            <material name="">
                <color rgba="0.79216 0.81961 0.93333 1" />
            </material>
        </visual>
        <collision>
            <origin rpy="0 0 0" xyz="0 0 0" />
            <geometry>
                <mesh filename="package://robot_description/meshes/common/link_swivel_wheel_4_2.STL" />
            </geometry>
        </collision>
    </link>
    <joint name="joint_right_wheel" type="continuous">
        <origin rpy="0 0 0" xyz="-0.148 0.015574 -0.153" />
        <parent link="base_link_underpan" />
        <child link="link_right_wheel" />
        <axis xyz="1 0 0" />
        <limit effort="100" velocity="10" />
    </joint>
    <joint name="joint_left_wheel" type="continuous">
        <origin rpy="0 0 0" xyz="0.148 0.015574 -0.153" />
        <parent link="base_link_underpan" />
        <child link="link_left_wheel" />
        <axis xyz="-1 0 0" />
        <limit effort="100" velocity="10" />
    </joint>
    <joint name="joint_swivel_wheel_1_1" type="continuous">
        <origin rpy="0 0 0" xyz="0.124 -0.17843 -0.16254" />
        <parent link="base_link_underpan" />
        <child link="link_swivel_wheel_1_1" />
        <axis xyz="0 0 1" />
    </joint>
    <joint name="joint_swivel_wheel_1_2" type="continuous">
        <origin rpy="0 0 0" xyz="-0.0035 -0.022 -0.04516" />
        <parent link="link_swivel_wheel_1_1" />
        <child link="link_swivel_wheel_1_2" />
        <axis xyz="1 0 0" />
    </joint>
    <joint name="joint_swivel_wheel_2_1" type="continuous">
        <origin rpy="0 0 0" xyz="-0.126 0.22157 -0.16254" />
        <parent link="base_link_underpan" />
        <child link="link_swivel_wheel_2_1" />
        <axis xyz="0 0 1" />
    </joint>
    <joint name="joint_swivel_wheel_2_2" type="continuous">
        <origin rpy="0 0 0" xyz="-0.0035 -0.022 -0.04516" />
        <parent link="link_swivel_wheel_2_1" />
        <child link="link_swivel_wheel_2_2" />
        <axis xyz="1 0 0" />
    </joint>
    <joint name="joint_swivel_wheel_3_1" type="continuous">
        <origin rpy="0 0 0" xyz="0.124 0.22157 -0.16254" />
        <parent link="base_link_underpan" />
        <child link="link_swivel_wheel_3_1" />
        <axis xyz="0 0 1" />
    </joint>
    <joint name="joint_swivel_wheel_3_2" type="continuous">
        <origin rpy="0 0 0" xyz="-0.0035 -0.022 -0.04516" />
        <parent link="link_swivel_wheel_3_1" />
        <child link="link_swivel_wheel_3_2" />
        <axis xyz="1 0 0" />
    </joint>
    <joint name="joint_swivel_wheel_4_1" type="continuous">
        <origin rpy="0 0 0" xyz="-0.126 -0.17843 -0.1665" />
        <parent link="base_link_underpan" />
        <child link="link_swivel_wheel_4_1" />
        <axis xyz="0 0 1" />
    </joint>
    <joint name="joint_swivel_wheel_4_2" type="continuous">
        <origin rpy="0 0 0" xyz="-0.0035 -0.022 -0.0412" />
        <parent link="link_swivel_wheel_4_1" />
        <child link="link_swivel_wheel_4_2" />
        <axis xyz="1 0 0" />
    </joint>
    <link name="body_base_link">
        <inertial>
            <origin rpy="0 0 0" xyz="-0.0002128 -0.02749 0.37118" />
            <mass value="12.159" />
            <inertia ixx="0.69175" ixy="3.0303E-06" ixz="-1.7947E-05" iyy="0.68839" iyz="0.012363" izz="0.15316" />
        </inertial>
        <visual>
            <origin rpy="0 0 0" xyz="0 0 0" />
            <geometry>
                <mesh filename="package://robot_description/meshes/common/body_base_link.STL" />
            </geometry>
            <material name="">
                <color rgba="0.79216 0.81961 0.93333 1" />
            </material>
        </visual>
        <collision>
            <origin rpy="0 0 0" xyz="0 0 0" />
            <geometry>
                <mesh filename="package://robot_description/meshes/common/body_base_link.STL" />
            </geometry>
        </collision>
    </link>
    <link name="platform_base_link">
        <inertial>
            <origin rpy="0 0 0" xyz="-4.8033E-05 -0.05292 0.00070789" />
            <mass value="2.8992" />
            <inertia ixx="0.013327" ixy="3.14E-06" ixz="3.5257E-06" iyy="0.032331" iyz="6.163E-05" izz="0.021546" />
        </inertial>
        <visual>
            <origin rpy="0 0 0" xyz="0 0 0" />
            <geometry>
                <mesh filename="package://robot_description/meshes/common/platform_base_link.STL" />
            </geometry>
            <material name="">
                <color rgba="0.79216 0.81961 0.93333 1" />
            </material>
        </visual>
        <collision>
            <origin rpy="0 0 0" xyz="0 0 0" />
            <geometry>
                <mesh filename="package://robot_description/meshes/common/platform_base_link.STL" />
            </geometry>
        </collision>
    </link>
    <link name="head_link1">
        <inertial>
            <origin rpy="0 0 0" xyz="-0.00017562 -0.015989 0.024926" />
            <mass value="0.049513" />
            <inertia ixx="1.6251E-05" ixy="-4.4281E-09" ixz="7.808E-08" iyy="2.2171E-05" iyz="-4.661E-07" izz="1.3605E-05" />
        </inertial>
        <visual>
            <origin rpy="0 0 0" xyz="0 0 0" />
            <geometry>
                <mesh filename="package://robot_description/meshes/common/head_link1.STL" />
            </geometry>
            <material name="">
                <color rgba="0.79216 0.81961 0.93333 1" />
            </material>
        </visual>
        <collision>
            <origin rpy="0 0 0" xyz="0 0 0" />
            <geometry>
                <mesh filename="package://robot_description/meshes/common/head_link1.STL" />
            </geometry>
        </collision>
    </link>
    <link name="head_link2">
        <inertial>
            <origin rpy="0 0 0" xyz="-0.00051349 -0.027144 0.0551" />
            <mass value="0.23639" />
            <inertia ixx="0.00025664" ixy="-1.6537E-08" ixz="1.3993E-07" iyy="0.0005615" iyz="1.8036E-05" izz="0.00052625" />
        </inertial>
        <visual>
            <origin rpy="0 0 0" xyz="0 0 0" />
            <geometry>
                <mesh filename="package://robot_description/meshes/common/head_link2.STL" />
            </geometry>
            <material name="">
                <color rgba="0.79216 0.81961 0.93333 1" />
            </material>
        </visual>
        <collision>
            <origin rpy="0 0 0" xyz="0 0 0" />
            <geometry>
                <mesh filename="package://robot_description/meshes/common/head_link2.STL" />
            </geometry>
        </collision>
    </link>
    <link name="camera_link">
        <inertial>
            <origin rpy="0 0 0" xyz="0.0016556 -0.01252 1.2156E-05" />
            <mass value="0.049778" />
            <inertia ixx="4.8577E-06" ixy="4.3442E-07" ixz="-6.2436E-10" iyy="3.075E-05" iyz="6.4645E-10" izz="3.0901E-05" />
        </inertial>
        <visual>
            <origin rpy="0 0 0" xyz="0 0 0" />
            <geometry>
                <mesh filename="package://robot_description/meshes/common/camera_link.STL" />
            </geometry>
            <material name="">
                <color rgba="0.79216 0.81961 0.93333 1" />
            </material>
        </visual>
        <collision>
            <origin rpy="0 0 0" xyz="0 0 0" />
            <geometry>
                <mesh filename="package://robot_description/meshes/common/camera_link.STL" />
            </geometry>
        </collision>
    </link>
    <joint name="platform_joint" type="prismatic">
        <origin rpy="0 0 0" xyz="0 -0.11663 1.271" />
        <parent link="body_base_link" />
        <child link="platform_base_link" />
        <axis xyz="0 0 -1" />
        <limit effort="60" lower="0" upper="1" velocity="0.15" />
    </joint>
    <joint name="head_joint1" type="revolute">
        <origin rpy="0 0 0" xyz="0 -0.1018 0.126" />
        <parent link="platform_base_link" />
        <child link="head_link1" />
        <axis xyz="0 0 1" />
        <limit effort="2" lower="-1.256" upper="1.256" velocity="1.57" />
    </joint>
    <joint name="head_joint2" type="revolute">
        <origin rpy="0 0 0" xyz="0 -0.02 0.044" />
        <parent link="head_link1" />
        <child link="head_link2" />
        <axis xyz="-1 0 0" />
        <limit effort="2" lower="-0.419" upper="0.419" velocity="1.57" />
    </joint>
    <joint name="camera_joint" type="fixed">
        <origin rpy="0 0 0" xyz="-0.0032391 -0.051866 0.061606" />
        <parent link="head_link2" />
        <child link="camera_link" />
        <axis xyz="0 0 0" />
    </joint>
    <link name="l_base_link_rmg24">
        <inertial>
            <origin rpy="0 0 0" xyz="4.891E-05 -5.4407E-05 0.04689" />
            <mass value="0.8" />
            <inertia ixx="6.6604E-05" ixy="-7.1616E-07" ixz="-3.2951E-07" iyy="0.00011614" iyz="1.1612E-07" izz="0.00012473" />
        </inertial>
        <visual>
            <origin rpy="0 0 0" xyz="0 0 0" />
            <geometry>
                <mesh filename="package://robot_description/meshes/rmg24/base_link2.STL" />
            </geometry>
            <material name="">
                <color rgba="0.75294 0.75294 0.75294 1" />
            </material>
        </visual>
        <collision>
            <origin rpy="0 0 0" xyz="0 0 0" />
            <geometry>
                <mesh filename="package://robot_description/meshes/rmg24/base_link2.STL" />
            </geometry>
        </collision>
    </link>
    <link name="l_Link_finger1">
        <inertial>
            <origin rpy="0 0 0" xyz="-0.0083779 -0.0014014 0.016575" />
            <mass value="0.2" />
            <inertia ixx="4.0976E-06" ixy="2.6578E-08" ixz="-4.8182E-07" iyy="3.8635E-06" iyz="6.1731E-08" izz="1.6965E-06" />
        </inertial>
        <visual>
            <origin rpy="0 0 0" xyz="0 0 0" />
            <geometry>
                <mesh filename="package://robot_description/meshes/rmg24/Link_finger1.STL" />
            </geometry>
            <material name="">
                <color rgba="0.75294 0.75294 0.75294 1" />
            </material>
        </visual>
        <collision>
            <origin rpy="0 0 0" xyz="0 0 0" />
            <geometry>
                <mesh filename="package://robot_description/meshes/rmg24/Link_finger1.STL" />
            </geometry>
        </collision>
    </link>
    <link name="l_Link_finger2">
        <inertial>
            <origin rpy="0 0 0" xyz="0.0083779 0.001392 0.016575" />
            <mass value="0.2" />
            <inertia ixx="4.0976E-06" ixy="2.6578E-08" ixz="4.8182E-07" iyy="3.8635E-06" iyz="-6.1731E-08" izz="1.6965E-06" />
        </inertial>
        <visual>
            <origin rpy="0 0 0" xyz="0 0 0" />
            <geometry>
                <mesh filename="package://robot_description/meshes/rmg24/Link_finger2.STL" />
            </geometry>
            <material name="">
                <color rgba="0.75294 0.75294 0.75294 1" />
            </material>
        </visual>
        <collision>
            <origin rpy="0 0 0" xyz="0 0 0" />
            <geometry>
                <mesh filename="package://robot_description/meshes/rmg24/Link_finger2.STL" />
            </geometry>
        </collision>
    </link>
    <joint name="l_Joint_finger1" type="prismatic">
        <origin rpy="0 0 0" xyz="0 0 0.0891" />
        <parent link="l_base_link_rmg24" />
        <child link="l_Link_finger1" />
        <axis xyz="-1 0 0" />
        <limit effort="10" lower="0" upper="0.0325" velocity="0.1" />
    </joint>
    <joint name="l_Joint_finger2" type="prismatic">
        <origin rpy="0 0 0" xyz="0 0 0.0891" />
        <parent link="l_base_link_rmg24" />
        <child link="l_Link_finger2" />
        <axis xyz="1 0 0" />
        <limit effort="10" lower="0" upper="0.0325" velocity="0.1" />
        <!-- <mimic joint="l_Joint_finger1" multiplier="1"  offset="0"/> -->
    </joint>
    <link name="r_base_link_rmg24">
        <inertial>
            <origin rpy="0 0 0" xyz="4.891E-05 -5.4407E-05 0.04689" />
            <mass value="0.8" />
            <inertia ixx="6.6604E-05" ixy="-7.1616E-07" ixz="-3.2951E-07" iyy="0.00011614" iyz="1.1612E-07" izz="0.00012473" />
        </inertial>
        <visual>
            <origin rpy="0 0 0" xyz="0 0 0" />
            <geometry>
                <mesh filename="package://robot_description/meshes/rmg24/base_link2.STL" />
            </geometry>
            <material name="">
                <color rgba="0.75294 0.75294 0.75294 1" />
            </material>
        </visual>
        <collision>
            <origin rpy="0 0 0" xyz="0 0 0" />
            <geometry>
                <mesh filename="package://robot_description/meshes/rmg24/base_link2.STL" />
            </geometry>
        </collision>
    </link>
    <link name="r_Link_finger1">
        <inertial>
            <origin rpy="0 0 0" xyz="-0.0083779 -0.0014014 0.016575" />
            <mass value="0.2" />
            <inertia ixx="4.0976E-06" ixy="2.6578E-08" ixz="-4.8182E-07" iyy="3.8635E-06" iyz="6.1731E-08" izz="1.6965E-06" />
        </inertial>
        <visual>
            <origin rpy="0 0 0" xyz="0 0 0" />
            <geometry>
                <mesh filename="package://robot_description/meshes/rmg24/Link_finger1.STL" />
            </geometry>
            <material name="">
                <color rgba="0.75294 0.75294 0.75294 1" />
            </material>
        </visual>
        <collision>
            <origin rpy="0 0 0" xyz="0 0 0" />
            <geometry>
                <mesh filename="package://robot_description/meshes/rmg24/Link_finger1.STL" />
            </geometry>
        </collision>
    </link>
    <link name="r_Link_finger2">
        <inertial>
            <origin rpy="0 0 0" xyz="0.0083779 0.001392 0.016575" />
            <mass value="0.2" />
            <inertia ixx="4.0976E-06" ixy="2.6578E-08" ixz="4.8182E-07" iyy="3.8635E-06" iyz="-6.1731E-08" izz="1.6965E-06" />
        </inertial>
        <visual>
            <origin rpy="0 0 0" xyz="0 0 0" />
            <geometry>
                <mesh filename="package://robot_description/meshes/rmg24/Link_finger2.STL" />
            </geometry>
            <material name="">
                <color rgba="0.75294 0.75294 0.75294 1" />
            </material>
        </visual>
        <collision>
            <origin rpy="0 0 0" xyz="0 0 0" />
            <geometry>
                <mesh filename="package://robot_description/meshes/rmg24/Link_finger2.STL" />
            </geometry>
        </collision>
    </link>
    <joint name="r_Joint_finger1" type="prismatic">
        <origin rpy="0 0 0" xyz="0 0 0.0891" />
        <parent link="r_base_link_rmg24" />
        <child link="r_Link_finger1" />
        <axis xyz="-1 0 0" />
        <limit effort="10" lower="0" upper="0.0325" velocity="0.1" />
    </joint>
    <joint name="r_Joint_finger2" type="prismatic">
        <origin rpy="0 0 0" xyz="0 0 0.0891" />
        <parent link="r_base_link_rmg24" />
        <child link="r_Link_finger2" />
        <axis xyz="1 0 0" />
        <limit effort="10" lower="0" upper="0.0325" velocity="0.1" />
        <!-- <mimic joint="r_Joint_finger1" multiplier="1"  offset="0"/> -->
    </joint>
    <link name="l_base_link1">
        <inertial>
            <origin rpy="0 0 0" xyz="-3.58E-05 -0.0056915 0.024464" />
            <mass value="0.23441" />
            <inertia ixx="0.00027369" ixy="6.5702E-08" ixz="2.7812E-09" iyy="0.000264" iyz="-1.6355E-06" izz="0.00036679" />
        </inertial>
        <visual>
            <origin rpy="0 0 0" xyz="0 0 0" />
            <geometry>
                <mesh filename="package://robot_description/meshes/common/l_base_link1.STL" />
            </geometry>
            <material name="">
                <color rgba="0.79216 0.81961 0.93333 1" />
            </material>
        </visual>
        <collision>
            <origin rpy="0 0 0" xyz="0 0 0" />
            <geometry>
                <mesh filename="package://robot_description/meshes/common/l_base_link1.STL" />
            </geometry>
        </collision>
    </link>
    <link name="l_link1">
        <inertial>
            <origin rpy="0 0 0" xyz="-2.9675E-07 0.021107 -0.025188" />
            <mass value="0.59353" />
            <inertia ixx="0.0012661" ixy="-5.363E-09" ixz="-2.109E-09" iyy="0.0011816" iyz="-0.00021118" izz="0.00056131" />
        </inertial>
        <visual>
            <origin rpy="0 0 0" xyz="0 0 0" />
            <geometry>
                <mesh filename="package://robot_description/meshes/rm65/l_link1.STL" />
            </geometry>
            <material name="">
                <color rgba="0.79216 0.81961 0.93333 1" />
            </material>
        </visual>
        <collision>
            <origin rpy="0 0 0" xyz="0 0 0" />
            <geometry>
                <mesh filename="package://robot_description/meshes/rm65/l_link1.STL" />
            </geometry>
        </collision>
    </link>
    <link name="l_link2">
        <inertial>
            <origin rpy="0 0 0" xyz="0.15226 2.3916E-07 -0.0062027" />
            <mass value="0.86416" />
            <inertia ixx="0.00063253" ixy="2.0103E-09" ixz="0.00042162" iyy="0.0020527" iyz="3.5857E-09" izz="0.0019528" />
        </inertial>
        <visual>
            <origin rpy="0 0 0" xyz="0 0 0" />
            <geometry>
                <mesh filename="package://robot_description/meshes/rm65/l_link2.STL" />
            </geometry>
            <material name="">
                <color rgba="0.79216 0.81961 0.93333 1" />
            </material>
        </visual>
        <collision>
            <origin rpy="0 0 0" xyz="0 0 0" />
            <geometry>
                <mesh filename="package://robot_description/meshes/rm65/l_link2.STL" />
            </geometry>
        </collision>
    </link>
    <link name="l_link3">
        <inertial>
            <origin rpy="0 0 0" xyz="4.7194E-06 -0.059592 0.010268" />
            <mass value="0.28963" />
            <inertia ixx="0.00063737" ixy="-6.2601E-08" ixz="-3.5046E-08" iyy="0.00015649" iyz="-0.00014461" izz="0.00061418" />
        </inertial>
        <visual>
            <origin rpy="0 0 0" xyz="0 0 0" />
            <geometry>
                <mesh filename="package://robot_description/meshes/rm65/l_link3.STL" />
            </geometry>
            <material name="">
                <color rgba="0.79216 0.81961 0.93333 1" />
            </material>
        </visual>
        <collision>
            <origin rpy="0 0 0" xyz="0 0 0" />
            <geometry>
                <mesh filename="package://robot_description/meshes/rm65/l_link3.STL" />
            </geometry>
        </collision>
    </link>
    <link name="l_link4">
        <inertial>
            <origin rpy="0 0 0" xyz="2.9186E-07 -0.018042 -0.02154" />
            <mass value="0.23942" />
            <inertia ixx="0.00028595" ixy="-2.3562E-09" ixz="1.3938E-09" iyy="0.00026273" iyz="4.424E-05" izz="0.0001199" />
        </inertial>
        <visual>
            <origin rpy="0 0 0" xyz="0 0 0" />
            <geometry>
                <mesh filename="package://robot_description/meshes/rm65/l_link4.STL" />
            </geometry>
            <material name="">
                <color rgba="0.79216 0.81961 0.93333 1" />
            </material>
        </visual>
        <collision>
            <origin rpy="0 0 0" xyz="0 0 0" />
            <geometry>
                <mesh filename="package://robot_description/meshes/rm65/l_link4.STL" />
            </geometry>
        </collision>
    </link>
    <link name="l_link5">
        <inertial>
            <origin rpy="0 0 0" xyz="4.2301E-06 -0.059381 0.0070671" />
            <mass value="0.21879" />
            <inertia ixx="0.00035053" ixy="-2.8554E-08" ixz="-1.67E-08" iyy="0.00010492" iyz="-7.824E-05" izz="0.00033447" />
        </inertial>
        <visual>
            <origin rpy="0 0 0" xyz="0 0 0" />
            <geometry>
                <mesh filename="package://robot_description/meshes/rm65/l_link5.STL" />
            </geometry>
            <material name="">
                <color rgba="0.79216 0.81961 0.93333 1" />
            </material>
        </visual>
        <collision>
            <origin rpy="0 0 0" xyz="0 0 0" />
            <geometry>
                <mesh filename="package://robot_description/meshes/rm65/l_link5.STL" />
            </geometry>
        </collision>
    </link>
    <link name="l_link6">
        <inertial>
            <origin rpy="0 0 0" xyz="0.028764 -5.1529E-06 0.025085" />
            <mass value="0.22147" />
            <inertia ixx="0.0001376" ixy="-5.7488E-08" ixz="-1.6634E-05" iyy="0.00026855" iyz="1.7799E-08" izz="0.00035277" />
        </inertial>
        <visual>
            <origin rpy="0 0 0" xyz="0 0 0" />
            <geometry>
                <mesh filename="package://robot_description/meshes/rm65/l_link6.STL" />
            </geometry>
            <material name="">
                <color rgba="0.79216 0.81961 0.93333 1" />
            </material>
        </visual>
        <collision>
            <origin rpy="0 0 0" xyz="0 0 0" />
            <geometry>
                <mesh filename="package://robot_description/meshes/rm65/l_link6.STL" />
            </geometry>
        </collision>
    </link>
    <joint name="l_joint1" type="revolute">
        <origin rpy="0 0 3.1415" xyz="0 0 0.187" />
        <parent link="l_base_link1" />
        <child link="l_link1" />
        <axis xyz="0 0 1" />
        <limit effort="60" lower="-3.11" upper="3.11" velocity="3.14" />
    </joint>
    <joint name="l_joint2" type="revolute">
        <origin rpy="1.5708 -1.5708 0" xyz="0 0 0" />
        <parent link="l_link1" />
        <child link="l_link2" />
        <axis xyz="0 0 1" />
        <limit effort="60" lower="-2.27" upper="2.27" velocity="3.14" />
    </joint>
    <joint name="l_joint3" type="revolute">
        <origin rpy="0 0 1.5708" xyz="0.256 0 0" />
        <parent link="l_link2" />
        <child link="l_link3" />
        <axis xyz="0 0 1" />
        <limit effort="30" lower="-2.36" upper="2.36" velocity="3.925" />
    </joint>
    <joint name="l_joint4" type="revolute">
        <origin rpy="1.5708 0 0" xyz="0 -0.21 -0.00030007" />
        <parent link="l_link3" />
        <child link="l_link4" />
        <axis xyz="0 0 1" />
        <limit effort="10" lower="-3.11" upper="3.11" velocity="3.925" />
    </joint>
    <joint name="l_joint5" type="revolute">
        <origin rpy="-1.5708 0 0" xyz="0 0 0" />
        <parent link="l_link4" />
        <child link="l_link5" />
        <axis xyz="0 0 1" />
        <limit effort="10" lower="-2.23" upper="2.23" velocity="3.925" />
    </joint>
    <joint name="l_joint6" type="revolute">
        <origin rpy="-1.5708 0 0" xyz="0 -0.115 -0.00029971" />
        <parent link="l_link5" />
        <child link="l_link6" />
        <axis xyz="0 0 -1" />
        <limit effort="10" lower="-6.28" upper="6.28" velocity="3.925" />
    </joint>
    <link name="r_base_link1">
        <inertial>
            <origin rpy="0 0 0" xyz="-4.8022E-05 0.0056915 0.024715" />
            <mass value="0.23441" />
            <inertia ixx="0.00027369" ixy="6.5702E-08" ixz="-3.2599E-09" iyy="0.000264" iyz="1.6355E-06" izz="0.00036679" />
        </inertial>
        <visual>
            <origin rpy="0 0 0" xyz="0 0 0" />
            <geometry>
                <mesh filename="package://robot_description/meshes/common/r_base_link1.STL" />
            </geometry>
            <material name="">
                <color rgba="0.79216 0.81961 0.93333 1" />
            </material>
        </visual>
        <collision>
            <origin rpy="0 0 0" xyz="0 0 0" />
            <geometry>
                <mesh filename="package://robot_description/meshes/common/r_base_link1.STL" />
            </geometry>
        </collision>
    </link>
    <link name="r_link1">
        <inertial>
            <origin rpy="0 0 0" xyz="-2.8998E-07 0.021107 -0.025188" />
            <mass value="0.59353" />
            <inertia ixx="0.0012661" ixy="-5.3526E-09" ixz="-2.0479E-09" iyy="0.0011816" iyz="-0.00021118" izz="0.00056131" />
        </inertial>
        <visual>
            <origin rpy="0 0 0" xyz="0 0 0" />
            <geometry>
                <mesh filename="package://robot_description/meshes/rm65/r_link1.STL" />
            </geometry>
            <material name="">
                <color rgba="0.79216 0.81961 0.93333 1" />
            </material>
        </visual>
        <collision>
            <origin rpy="0 0 0" xyz="0 0 0" />
            <geometry>
                <mesh filename="package://robot_description/meshes/rm65/r_link1.STL" />
            </geometry>
        </collision>
    </link>
    <link name="r_link2">
        <inertial>
            <origin rpy="0 0 0" xyz="0.15226 2.505E-07 -0.0062027" />
            <mass value="0.86416" />
            <inertia ixx="0.00063253" ixy="1.9052E-09" ixz="0.00042162" iyy="0.0020527" iyz="3.5874E-09" izz="0.0019528" />
        </inertial>
        <visual>
            <origin rpy="0 0 0" xyz="0 0 0" />
            <geometry>
                <mesh filename="package://robot_description/meshes/rm65/r_link2.STL" />
            </geometry>
            <material name="">
                <color rgba="0.79216 0.81961 0.93333 1" />
            </material>
        </visual>
        <collision>
            <origin rpy="0 0 0" xyz="0 0 0" />
            <geometry>
                <mesh filename="package://robot_description/meshes/rm65/r_link2.STL" />
            </geometry>
        </collision>
    </link>
    <link name="r_link3">
        <inertial>
            <origin rpy="0 0 0" xyz="4.7421E-06 -0.059592 0.010268" />
            <mass value="0.28963" />
            <inertia ixx="0.00063737" ixy="-6.2554E-08" ixz="-3.5031E-08" iyy="0.00015649" iyz="-0.00014461" izz="0.00061418" />
        </inertial>
        <visual>
            <origin rpy="0 0 0" xyz="0 0 0" />
            <geometry>
                <mesh filename="package://robot_description/meshes/rm65/r_link3.STL" />
            </geometry>
            <material name="">
                <color rgba="0.79216 0.81961 0.93333 1" />
            </material>
        </visual>
        <collision>
            <origin rpy="0 0 0" xyz="0 0 0" />
            <geometry>
                <mesh filename="package://robot_description/meshes/rm65/r_link3.STL" />
            </geometry>
        </collision>
    </link>
    <link name="r_link4">
        <inertial>
            <origin rpy="0 0 0" xyz="2.9088E-07 -0.018042 -0.02154" />
            <mass value="0.23942" />
            <inertia ixx="0.00028595" ixy="-2.3541E-09" ixz="1.386E-09" iyy="0.00026273" iyz="4.424E-05" izz="0.0001199" />
        </inertial>
        <visual>
            <origin rpy="0 0 0" xyz="0 0 0" />
            <geometry>
                <mesh filename="package://robot_description/meshes/rm65/r_link4.STL" />
            </geometry>
            <material name="">
                <color rgba="0.79216 0.81961 0.93333 1" />
            </material>
        </visual>
        <collision>
            <origin rpy="0 0 0" xyz="0 0 0" />
            <geometry>
                <mesh filename="package://robot_description/meshes/rm65/r_link4.STL" />
            </geometry>
        </collision>
    </link>
    <link name="r_link5">
        <inertial>
            <origin rpy="0 0 0" xyz="4.2478E-06 -0.059381 0.007067" />
            <mass value="0.21879" />
            <inertia ixx="0.00035053" ixy="-2.8579E-08" ixz="-1.655E-08" iyy="0.00010492" iyz="-7.824E-05" izz="0.00033447" />
        </inertial>
        <visual>
            <origin rpy="0 0 0" xyz="0 0 0" />
            <geometry>
                <mesh filename="package://robot_description/meshes/rm65/r_link5.STL" />
            </geometry>
            <material name="">
                <color rgba="0.79216 0.81961 0.93333 1" />
            </material>
        </visual>
        <collision>
            <origin rpy="0 0 0" xyz="0 0 0" />
            <geometry>
                <mesh filename="package://robot_description/meshes/rm65/r_link5.STL" />
            </geometry>
        </collision>
    </link>
    <link name="r_link6">
        <inertial>
            <origin rpy="0 0 0" xyz="-0.028764 5.1464E-06 0.02806" />
            <mass value="0.22147" />
            <inertia ixx="0.0001376" ixy="-5.7488E-08" ixz="1.6634E-05" iyy="0.00026855" iyz="-1.7799E-08" izz="0.00035277" />
        </inertial>
        <visual>
            <origin rpy="0 0 0" xyz="0 0 0" />
            <geometry>
                <mesh filename="package://robot_description/meshes/rm65/r_link6.STL" />
            </geometry>
            <material name="">
                <color rgba="0.79216 0.81961 0.93333 1" />
            </material>
        </visual>
        <collision>
            <origin rpy="0 0 0" xyz="0 0 0" />
            <geometry>
                <mesh filename="package://robot_description/meshes/rm65/r_link6.STL" />
            </geometry>
        </collision>
    </link>
    <joint name="r_joint1" type="revolute">
        <origin rpy="0 0 0" xyz="0 0 0.187" />
        <parent link="r_base_link1" />
        <child link="r_link1" />
        <axis xyz="0 0 1" />
        <limit effort="60" lower="-3.11" upper="3.11" velocity="3.14" />
    </joint>
    <joint name="r_joint2" type="revolute">
        <origin rpy="1.5708 -1.5708 0" xyz="0 0 0" />
        <parent link="r_link1" />
        <child link="r_link2" />
        <axis xyz="0 0 1" />
        <limit effort="60" lower="-2.27" upper="2.27" velocity="3.14" />
    </joint>
    <joint name="r_joint3" type="revolute">
        <origin rpy="0 0 1.5708" xyz="0.256 0 0" />
        <parent link="r_link2" />
        <child link="r_link3" />
        <axis xyz="0 0 1" />
        <limit effort="30" lower="-2.36" upper="2.36" velocity="3.925" />
    </joint>
    <joint name="r_joint4" type="revolute">
        <origin rpy="1.5708 0 0" xyz="0 -0.21 -0.00030007" />
        <parent link="r_link3" />
        <child link="r_link4" />
        <axis xyz="0 0 1" />
        <limit effort="10" lower="-3.11" upper="3.11" velocity="3.925" />
    </joint>
    <joint name="r_joint5" type="revolute">
        <origin rpy="-1.5708 0 0" xyz="0 0 0" />
        <parent link="r_link4" />
        <child link="r_link5" />
        <axis xyz="0 0 1" />
        <limit effort="10" lower="-2.23" upper="2.23" velocity="3.925" />
    </joint>
    <joint name="r_joint6" type="revolute">
        <origin rpy="1.5708 0 0" xyz="0 -0.11203 -0.00029971" />
        <parent link="r_link5" />
        <child link="r_link6" />
        <axis xyz="0 0 1" />
        <limit effort="10" lower="-6.28" upper="6.28" velocity="3.925" />
    </joint>
    <joint name="body_base_joint" type="fixed">
        <origin rpy="0 0 0" xyz="0 0 0" />
        <parent link="base_link_underpan" />
        <child link="body_base_link" />
        <axis xyz="1 0 0" />
        <limit effort="0" velocity="0" />
    </joint>
    <joint name="r_base_joint1" type="fixed">
        <origin rpy="0 -0.7854 0" xyz="-0.1 -0.1103 0.031645" />
        <parent link="platform_base_link" />
        <child link="r_base_link1" />
        <axis xyz="0 0 0" />
    </joint>
    <joint name="l_base_joint1" type="fixed">
        <origin rpy="0 -0.7854 3.1416" xyz="0.1 -0.1103 0.031645" />
        <parent link="platform_base_link" />
        <child link="l_base_link1" />
        <axis xyz="0 0 0" />
    </joint>
    <!-- <joint
    name="r_hand_joint"
    type="fixed">
    <origin
      xyz="0 0 0.0445"
      rpy="0 0 1.57" />
    <parent
      link="r_link6" />
    <child
      link="r_base_link_rmg24" />
    <axis
      xyz="0 0 -1" />
    <limit
      lower="0"
      upper="0"
      effort="0"
      velocity="0" />
  </joint>  
  <joint
    name="l_hand_joint"
    type="fixed">
    <origin
      xyz="0 0 0.0445"
      rpy="0 3.1415 1.57" />
    <parent
      link="l_link6" />
    <child
      link="l_base_link_rmg24" />
    <axis
      xyz="0 0 0" />
    <limit
      lower="0"
      upper="0"
      effort="0"
      velocity="0" />
  </joint>   -->
    <joint name="r_hand_joint" type="fixed">
        <origin rpy="0 0 1.57" xyz="0 0 0.046" />
        <parent link="r_link6" />
        <child link="r_base_link_rmg24" />
        <axis xyz="0 0 -1" />
        <limit effort="0" lower="0" upper="0" velocity="0" />
    </joint>
    <joint name="l_hand_joint" type="fixed">
        <origin rpy="0 3.1415 1.57" xyz="0 0 -0.0015" />
        <parent link="l_link6" />
        <child link="l_base_link_rmg24" />
        <axis xyz="0 0 0" />
        <limit effort="0" lower="0" upper="0" velocity="0" />
    </joint>
    <gazebo>
        <plugin filename="libgazebo_ros_control.so" name="control">
            <robotNamespace>/</robotNamespace>
            <robotSimType>gazebo_ros_control/DefaultRobotHWSim</robotSimType>
            <legacyModeNS>true</legacyModeNS>
        </plugin>
        <plugin name="gazebo_ros_control" filename="libgazebo_ros_control.so">
            <robotNamespace>/</robotNamespace>
        </plugin>
    </gazebo>
    <transmission name="l_joint1_trans">
        <type>transmission_interface/SimpleTransmission</type>
        <joint name="l_joint1">
            <hardwareInterface>PositionJointInterface</hardwareInterface>
        </joint>
        <actuator name="l_joint1_motor">
            <mechanicalReduction>1</mechanicalReduction>
            <hardwareInterface>hardware_interface/EffortJointInterface</hardwareInterface>
        </actuator>
    </transmission>
    <transmission name="l_joint2_trans">
        <type>transmission_interface/SimpleTransmission</type>
        <joint name="l_joint2">
            <hardwareInterface>PositionJointInterface</hardwareInterface>
        </joint>
        <actuator name="l_joint2_motor">
            <mechanicalReduction>1</mechanicalReduction>
            <hardwareInterface>hardware_interface/EffortJointInterface</hardwareInterface>
        </actuator>
    </transmission>
    <transmission name="l_joint3_trans">
        <type>transmission_interface/SimpleTransmission</type>
        <joint name="l_joint3">
            <hardwareInterface>PositionJointInterface</hardwareInterface>
        </joint>
        <actuator name="l_joint3_motor">
            <mechanicalReduction>1</mechanicalReduction>
            <hardwareInterface>hardware_interface/EffortJointInterface</hardwareInterface>
        </actuator>
    </transmission>
    <transmission name="l_joint4_trans">
        <type>transmission_interface/SimpleTransmission</type>
        <joint name="l_joint4">
            <hardwareInterface>PositionJointInterface</hardwareInterface>
        </joint>
        <actuator name="l_joint4_motor">
            <mechanicalReduction>1</mechanicalReduction>
            <hardwareInterface>hardware_interface/EffortJointInterface</hardwareInterface>
        </actuator>
    </transmission>
    <transmission name="l_joint5_trans">
        <type>transmission_interface/SimpleTransmission</type>
        <joint name="l_joint5">
            <hardwareInterface>PositionJointInterface</hardwareInterface>
        </joint>
        <actuator name="l_joint5_motor">
            <mechanicalReduction>1</mechanicalReduction>
            <hardwareInterface>hardware_interface/EffortJointInterface</hardwareInterface>
        </actuator>
    </transmission>
    <transmission name="l_joint6_trans">
        <type>transmission_interface/SimpleTransmission</type>
        <joint name="l_joint6">
            <hardwareInterface>PositionJointInterface</hardwareInterface>
        </joint>
        <actuator name="l_joint6_motor">
            <mechanicalReduction>1</mechanicalReduction>
            <hardwareInterface>hardware_interface/EffortJointInterface</hardwareInterface>
        </actuator>
    </transmission>
    <transmission name="r_joint1_trans">
        <type>transmission_interface/SimpleTransmission</type>
        <joint name="r_joint1">
            <hardwareInterface>PositionJointInterface</hardwareInterface>
        </joint>
        <actuator name="r_joint1_motor">
            <mechanicalReduction>1</mechanicalReduction>
            <hardwareInterface>hardware_interface/EffortJointInterface</hardwareInterface>
        </actuator>
    </transmission>
    <transmission name="r_joint2_trans">
        <type>transmission_interface/SimpleTransmission</type>
        <joint name="r_joint2">
            <hardwareInterface>PositionJointInterface</hardwareInterface>
        </joint>
        <actuator name="r_joint2_motor">
            <mechanicalReduction>1</mechanicalReduction>
            <hardwareInterface>hardware_interface/EffortJointInterface</hardwareInterface>
        </actuator>
    </transmission>
    <transmission name="r_joint3_trans">
        <type>transmission_interface/SimpleTransmission</type>
        <joint name="r_joint3">
            <hardwareInterface>PositionJointInterface</hardwareInterface>
        </joint>
        <actuator name="r_joint3_motor">
            <mechanicalReduction>1</mechanicalReduction>
            <hardwareInterface>hardware_interface/EffortJointInterface</hardwareInterface>
        </actuator>
    </transmission>
    <transmission name="r_joint4_trans">
        <type>transmission_interface/SimpleTransmission</type>
        <joint name="r_joint4">
            <hardwareInterface>PositionJointInterface</hardwareInterface>
        </joint>
        <actuator name="r_joint4_motor">
            <mechanicalReduction>1</mechanicalReduction>
            <hardwareInterface>hardware_interface/EffortJointInterface</hardwareInterface>
        </actuator>
    </transmission>
    <transmission name="r_joint5_trans">
        <type>transmission_interface/SimpleTransmission</type>
        <joint name="r_joint5">
            <hardwareInterface>PositionJointInterface</hardwareInterface>
        </joint>
        <actuator name="r_joint5_motor">
            <mechanicalReduction>1</mechanicalReduction>
            <hardwareInterface>hardware_interface/EffortJointInterface</hardwareInterface>
        </actuator>
    </transmission>
    <transmission name="r_joint6_trans">
        <type>transmission_interface/SimpleTransmission</type>
        <joint name="r_joint6">
            <hardwareInterface>PositionJointInterface</hardwareInterface>
        </joint>
        <actuator name="r_joint6_motor">
            <mechanicalReduction>1</mechanicalReduction>
            <hardwareInterface>hardware_interface/EffortJointInterface</hardwareInterface>
        </actuator>
    </transmission>
    <transmission name="Joint_finger1_trans">
        <type>transmission_interface/SimpleTransmission</type>
        <joint name="l_Joint_finger1">
            <hardwareInterface>PositionJointInterface</hardwareInterface>
        </joint>
        <actuator name="actuator_finger1">
            <hardwareInterface>PositionJointInterface</hardwareInterface>
            <mechanicalReduction>1</mechanicalReduction>
        </actuator>
    </transmission>
    <!-- Joint_finger2 是一个从动关节，通过 mimic 实现 -->
    <!-- 如果 Joint_finger2 由同一个执行器驱动，可以省略其传动定义 -->
    <transmission name="Joint_finger2_trans">
        <type>transmission_interface/SimpleTransmission</type>
        <joint name="l_Joint_finger2">
            <hardwareInterface>PositionJointInterface</hardwareInterface>
        </joint>
        <actuator name="actuator_finger2">
            <hardwareInterface>PositionJointInterface</hardwareInterface>
            <mechanicalReduction>1</mechanicalReduction>
        </actuator>
    </transmission>
    <transmission name="Joint_finger1_trans">
        <type>transmission_interface/SimpleTransmission</type>
        <joint name="r_Joint_finger1">
            <hardwareInterface>PositionJointInterface</hardwareInterface>
        </joint>
        <actuator name="actuator_finger1">
            <hardwareInterface>PositionJointInterface</hardwareInterface>
            <mechanicalReduction>1</mechanicalReduction>
        </actuator>
    </transmission>
    <!-- Joint_finger2 是一个从动关节，通过 mimic 实现 -->
    <!-- 如果 Joint_finger2 由同一个执行器驱动，可以省略其传动定义 -->
    <transmission name="Joint_finger2_trans">
        <type>transmission_interface/SimpleTransmission</type>
        <joint name="r_Joint_finger2">
            <hardwareInterface>PositionJointInterface</hardwareInterface>
        </joint>
        <actuator name="actuator_finger2">
            <hardwareInterface>PositionJointInterface</hardwareInterface>
            <mechanicalReduction>1</mechanicalReduction>
        </actuator>
    </transmission>
    <transmission name="platform_joint_trans">
        <type>transmission_interface/SimpleTransmission</type>
        <joint name="platform_joint">
            <hardwareInterface>PositionJointInterface</hardwareInterface>
        </joint>
        <actuator name="platform_joint_motor">
            <mechanicalReduction>1</mechanicalReduction>
            <hardwareInterface>hardware_interface/EffortJointInterface</hardwareInterface>
        </actuator>
    </transmission>
    <transmission name="head_joint1_trans">
        <type>transmission_interface/SimpleTransmission</type>
        <joint name="head_joint1">
            <hardwareInterface>PositionJointInterface</hardwareInterface>
        </joint>
        <actuator name="head_joint1_motor">
            <mechanicalReduction>1</mechanicalReduction>
            <hardwareInterface>hardware_interface/EffortJointInterface</hardwareInterface>
        </actuator>
    </transmission>
    <transmission name="head_joint2_trans">
        <type>transmission_interface/SimpleTransmission</type>
        <joint name="head_joint2">
            <hardwareInterface>PositionJointInterface</hardwareInterface>
        </joint>
        <actuator name="head_joint2_motor">
            <mechanicalReduction>1</mechanicalReduction>
            <hardwareInterface>hardware_interface/EffortJointInterface</hardwareInterface>
        </actuator>
    </transmission>
    <transmission name="trans_joint_right_wheel">
        <type>transmission_interface/SimpleTransmission</type>
        <joint name="joint_right_wheel">
            <hardwareInterface>hardware_interface/EffortJointInterface</hardwareInterface>
        </joint>
        <actuator name="joint_right_wheel_motor">
            <hardwareInterface>hardware_interface/EffortJointInterface</hardwareInterface>
            <mechanicalReduction>1</mechanicalReduction>
        </actuator>
    </transmission>
    <transmission name="trans_joint_left_wheel">
        <type>transmission_interface/SimpleTransmission</type>
        <joint name="joint_left_wheel">
            <hardwareInterface>hardware_interface/EffortJointInterface</hardwareInterface>
        </joint>
        <actuator name="joint_left_wheel_motor">
            <hardwareInterface>hardware_interface/EffortJointInterface</hardwareInterface>
            <mechanicalReduction>1</mechanicalReduction>
        </actuator>
    </transmission>
    <transmission name="trans_joint_swivel_wheel_1_1">
        <type>transmission_interface/SimpleTransmission</type>
        <joint name="joint_swivel_wheel_1_1">
            <hardwareInterface>hardware_interface/EffortJointInterface</hardwareInterface>
        </joint>
        <actuator name="joint_swivel_wheel_1_1_motor">
            <hardwareInterface>hardware_interface/EffortJointInterface</hardwareInterface>
            <mechanicalReduction>1</mechanicalReduction>
        </actuator>
    </transmission>
    <transmission name="trans_joint_swivel_wheel_1_2">
        <type>transmission_interface/SimpleTransmission</type>
        <joint name="joint_swivel_wheel_1_2">
            <hardwareInterface>hardware_interface/EffortJointInterface</hardwareInterface>
        </joint>
        <actuator name="joint_swivel_wheel_1_2_motor">
            <hardwareInterface>hardware_interface/EffortJointInterface</hardwareInterface>
            <mechanicalReduction>1</mechanicalReduction>
        </actuator>
    </transmission>
    <transmission name="trans_joint_swivel_wheel_2_1">
        <type>transmission_interface/SimpleTransmission</type>
        <joint name="joint_swivel_wheel_2_1">
            <hardwareInterface>hardware_interface/EffortJointInterface</hardwareInterface>
        </joint>
        <actuator name="joint_swivel_wheel_2_1_motor">
            <hardwareInterface>hardware_interface/EffortJointInterface</hardwareInterface>
            <mechanicalReduction>1</mechanicalReduction>
        </actuator>
    </transmission>
    <transmission name="trans_joint_swivel_wheel_2_2">
        <type>transmission_interface/SimpleTransmission</type>
        <joint name="joint_swivel_wheel_2_2">
            <hardwareInterface>hardware_interface/EffortJointInterface</hardwareInterface>
        </joint>
        <actuator name="joint_swivel_wheel_2_2_motor">
            <hardwareInterface>hardware_interface/EffortJointInterface</hardwareInterface>
            <mechanicalReduction>1</mechanicalReduction>
        </actuator>
    </transmission>
    <transmission name="trans_joint_swivel_wheel_3_1">
        <type>transmission_interface/SimpleTransmission</type>
        <joint name="joint_swivel_wheel_3_1">
            <hardwareInterface>hardware_interface/EffortJointInterface</hardwareInterface>
        </joint>
        <actuator name="joint_swivel_wheel_3_1_motor">
            <hardwareInterface>hardware_interface/EffortJointInterface</hardwareInterface>
            <mechanicalReduction>1</mechanicalReduction>
        </actuator>
    </transmission>
    <transmission name="trans_joint_swivel_wheel_3_2">
        <type>transmission_interface/SimpleTransmission</type>
        <joint name="joint_swivel_wheel_3_2">
            <hardwareInterface>hardware_interface/EffortJointInterface</hardwareInterface>
        </joint>
        <actuator name="joint_swivel_wheel_3_2_motor">
            <hardwareInterface>hardware_interface/EffortJointInterface</hardwareInterface>
            <mechanicalReduction>1</mechanicalReduction>
        </actuator>
    </transmission>
    <transmission name="trans_joint_swivel_wheel_4_1">
        <type>transmission_interface/SimpleTransmission</type>
        <joint name="joint_swivel_wheel_4_1">
            <hardwareInterface>hardware_interface/EffortJointInterface</hardwareInterface>
        </joint>
        <actuator name="joint_swivel_wheel_4_1_motor">
            <hardwareInterface>hardware_interface/EffortJointInterface</hardwareInterface>
            <mechanicalReduction>1</mechanicalReduction>
        </actuator>
    </transmission>
    <transmission name="trans_joint_swivel_wheel_4_2">
        <type>transmission_interface/SimpleTransmission</type>
        <joint name="joint_swivel_wheel_4_2">
            <hardwareInterface>hardware_interface/EffortJointInterface</hardwareInterface>
        </joint>
        <actuator name="joint_swivel_wheel_4_2_motor">
            <hardwareInterface>hardware_interface/EffortJointInterface</hardwareInterface>
            <mechanicalReduction>1</mechanicalReduction>
        </actuator>
    </transmission>
</robot>

