<?xml version="1.0"?>
<robot name="rm75_b_v_left" xmlns:xacro="http://www.ros.org/wiki/xacro">
  <!-- Define constants -->
  <xacro:property name="mesh_path" value="package://robot_description/meshes/rm75/" />
  <xacro:property name="mesh_path2" value="package://robot_description/meshes/common/" />
  <!-- Macro for visual and collision elements -->
  <xacro:macro name="visual_collision" params="mesh">
    <visual>
      <origin xyz="0 0 0" rpy="0 0 0" />
      <geometry>
        <mesh filename="${mesh_path}${mesh}" />
      </geometry>
      <material name="">
        <color rgba="0.79216 0.81961 0.93333 1" />
      </material>
    </visual>
    <collision>
      <origin xyz="0 0 0" rpy="0 0 0" />
      <geometry>
        <mesh filename="${mesh_path}${mesh}" />
      </geometry>
    </collision>
  </xacro:macro>
  <xacro:macro name="visual_collision2" params="mesh">
    <visual>
      <origin xyz="0 0 0" rpy="0 0 0" />
      <geometry>
        <mesh filename="${mesh_path2}${mesh}" />
      </geometry>
      <material name="">
        <color rgba="0.79216 0.81961 0.93333 1" />
      </material>
    </visual>
    <collision>
      <origin xyz="0 0 0" rpy="0 0 0" />
      <geometry>
        <mesh filename="${mesh_path2}${mesh}" />
      </geometry>
    </collision>
  </xacro:macro>
  <link
    name="l_base_link1">
    <inertial>
      <origin
        xyz="-3.58E-05 -0.0056915 0.024464"
        rpy="0 0 0" />
      <mass
        value="0.23441" />
      <inertia
        ixx="0.00027369"
        ixy="6.5702E-08"
        ixz="2.7812E-09"
        iyy="0.000264"
        iyz="-1.6355E-06"
        izz="0.00036679" />
    </inertial>
    <xacro:visual_collision2 mesh="l_base_link1.STL" />
  </link>
  <link
    name="l_link1">
    <inertial>
      <origin
        xyz="2.9692E-07 0.025188 -0.021107"
        rpy="0 0 0" />
      <mass
        value="0.59353" />
      <inertia
        ixx="0.0012661"
        ixy="-2.1134E-09"
        ixz="-5.3685E-09"
        iyy="0.00056131"
        iyz="-0.00021118"
        izz="0.0011816" />
    </inertial>
    <xacro:visual_collision mesh="l_link1.STL" />
  </link>
  <link
    name="l_link2">
    <inertial>
      <origin
        xyz="3.7598E-07 0.011077 0.07613"
        rpy="0 0 0" />
      <mass
        value="0.43285" />
      <inertia
        ixx="0.0012584"
        ixy="7.8046E-10"
        ixz="3.3823E-09"
        iyy="0.0012224"
        iyz="0.00027899"
        izz="0.00031747" />
    </inertial>
    <xacro:visual_collision mesh="l_link2.STL" />
  </link>
  <link
    name="l_link3">
    <inertial>
      <origin
        xyz="1.1341E-07 0.027347 -0.023544"
        rpy="0 0 0" />
      <mass
        value="0.43132" />
      <inertia
        ixx="0.00079434"
        ixy="1.4278E-09"
        ixz="2.8253E-09"
        iyy="0.00031506"
        iyz="-0.00014262"
        izz="0.00073038" />
    </inertial>
    <xacro:visual_collision mesh="l_link3.STL" />
  </link>
  <link
    name="l_link4">
    <inertial>
      <origin
        xyz="4.7315E-06 0.010268 0.059592"
        rpy="0 0 0" />
      <mass
        value="0.28963" />
      <inertia
        ixx="0.00063737"
        ixy="-3.5036E-08"
        ixz="6.2577E-08"
        iyy="0.00061418"
        iyz="0.00014461"
        izz="0.00015649" />
    </inertial>
    <xacro:visual_collision mesh="l_link4.STL" />
  </link>
  <link
    name="l_link5">
    <inertial>
      <origin
        xyz="2.93E-07 0.02154 -0.018042"
        rpy="0 0 0" />
      <mass
        value="0.23942" />
      <inertia
        ixx="0.00028595"
        ixy="-1.4023E-09"
        ixz="-2.3584E-09"
        iyy="0.0001199"
        iyz="-4.424E-05"
        izz="0.00026273" />
    </inertial>
    <xacro:visual_collision mesh="l_link5.STL" />
  </link>
  <link
    name="l_link6">
    <inertial>
      <origin
        xyz="4.2445E-06 0.007067 0.059381"
        rpy="0 0 0" />
      <mass
        value="0.21879" />
      <inertia
        ixx="0.00035053"
        ixy="-1.6558E-08"
        ixz="2.8592E-08"
        iyy="0.00033447"
        iyz="7.824E-05"
        izz="0.00010492" />
    </inertial>
    <xacro:visual_collision mesh="l_link6.STL" />
  </link>
  <link
    name="l_link7">
    <inertial>
      <origin
        xyz="-0.028763 5.1529E-06 0.025085"
        rpy="0 0 0" />
      <mass
        value="0.22147" />
      <inertia
        ixx="0.0001376"
        ixy="-5.7487E-08"
        ixz="1.6636E-05"
        iyy="0.00026856"
        iyz="-1.7799E-08"
        izz="0.00035278" />
    </inertial>
    <xacro:visual_collision mesh="l_link7.STL" />
  </link>
 <link
    name="l_link8">
    <inertial>
      <origin
        xyz="-0.0344776448483772 0.00494196667625979 -0.0105744697648362"
        rpy="0 0 0" />
      <mass
        value="0.102409228149193" />
      <inertia
        ixx="8.89659984561889E-05"
        ixy="2.51831111225342E-06"
        ixz="-1.02226936227776E-06"
        iyy="0.00010126709905583"
        iyz="7.68513067529592E-07"
        izz="3.88938021640452E-05" />
    </inertial>
    <xacro:visual_collision2 mesh="l_link8.STL" />
  </link>
  <link
    name="l_link9">
    <inertial>
      <origin
        xyz="-0.000425789891989048 -0.00198320133302361 0.0124868480183606"
        rpy="0 0 0" />
      <mass
        value="0.0314078534389695" />
      <inertia
        ixx="2.08249839281172E-05"
        ixy="9.91662953999129E-08"
        ixz="-2.07305447884078E-09"
        iyy="2.95509622657586E-06"
        iyz="3.39614376627076E-09"
        izz="2.06562510710468E-05" />
    </inertial>
    <xacro:visual_collision2 mesh="l_link9.STL" />
  </link>
  <joint
    name="l_joint1"
    type="revolute">
    <origin
      xyz="0 0 0.187"
      rpy="0 0 3.14" />
    <parent
      link="l_base_link1" />
    <child
      link="l_link1" />
    <axis
      xyz="0 0 1  " />
    <limit
      lower="-3.11"
      upper="3.11"
      effort="60"
      velocity="3.14" />
  </joint>
  <joint
    name="l_joint2"
    type="revolute">
    <origin
      xyz="0 0 0"
      rpy="1.57079632680005 -1.5707963267949 0" />
    <parent
      link="l_link1" />
    <child
      link="l_link2" />
    <axis
      xyz="0 0 1" />
    <limit
      lower="-2.27"
      upper="2.27"
      effort="60"
      velocity="3.14" />
  </joint>
  <joint
    name="l_joint3"
    type="revolute">
    <origin
      xyz="0.2559999999996 0 0"
      rpy="-1.5707963267949 0 -1.57079632679481" />
    <parent
      link="l_link2" />
    <child
      link="l_link3" />
    <axis
      xyz="0 0 1" />
    <limit
      lower="-3.11"
      upper="3.11"
      effort="30"
      velocity="3.925" />
  </joint>
  <joint
    name="l_joint4"
    type="revolute">
    <origin
      xyz="0 0 0"
      rpy="-1.5707963267949 0 -3.14159265358224" />
    <parent
      link="l_link3" />
    <child
      link="l_link4" />
    <axis
      xyz="0 0 1" />
    <limit
      lower="-2.36"
      upper="2.36"
      effort="30"
      velocity="3.925" />
  </joint>
  <joint
    name="l_joint5"
    type="revolute">
    <origin
      xyz="0 -0.209999999999999 0"
      rpy="1.5707963267949 0 0" />
    <parent
      link="l_link4" />
    <child
      link="l_link5" />
    <axis
      xyz="0 0 1" />
    <limit
      lower="-3.11"
      upper="3.11"
      effort="10"
      velocity="3.925" />
  </joint>
  <joint
    name="l_joint6"
    type="revolute">
    <origin
      xyz="0 0 0"
      rpy="-1.5707963267949 0 0" />
    <parent
      link="l_link5" />
    <child
      link="l_link6" />
    <axis
      xyz="0 0 1" />
    <limit
      lower="-2.23"
      upper="2.23"
      effort="10"
      velocity="3.14" />
  </joint>
  <joint
    name="l_joint7"
    type="revolute">
    <origin
      xyz="-0.000105285996034623 -0.1668 0.000407519296156477"
      rpy="1.5707963267949 3.14 0" />
    <parent
      link="l_link6" />
    <child
      link="l_link7" />
    <axis
      xyz="0 0 1" />
    <limit
      lower="-6.28"
      upper="6.28"
      effort="10"
      velocity="3.14" />
  </joint>

  <joint
    name="l_joint8"
    type="revolute">
    <origin
      xyz="-0.0448935903863956 -0.000107308776157644 -0.0365"
      rpy="1.57079632679488 3.14 0" />
    <parent
      link="l_link7" />
    <child
      link="l_link8" />
    <axis
      xyz="0 0 -1" />
    <limit
      lower="0"
      upper="0.79"
      effort="0"
      velocity="0" />
  </joint>
   <joint
    name="l_joint9"
    type="fixed">
    <origin
      xyz="0.02800001468744 -0.0187499999999561 -0.011499999939572"
      rpy="1.5707963267949 0 1.5707963267949" />
    <parent
      link="l_link8" />
    <child
      link="l_link9" />
    <axis
      xyz="0 0 0" />
  </joint>


</robot>
