<?xml version="1.0"?>
<robot name="rm65_b_v_left" xmlns:xacro="http://www.ros.org/wiki/xacro">
  <!-- Define constants -->
  <xacro:property name="mesh_path" value="package://robot_description/meshes/rm65/" />
  <xacro:property name="mesh_path2" value="package://robot_description/meshes/common/" />

  <!-- Macro for visual and collision elements -->
  <xacro:macro name="visual_collision" params="mesh">
    <visual>
      <origin xyz="0 0 0" rpy="0 0 0" />
      <geometry>
        <mesh filename="${mesh_path}${mesh}" />
      </geometry>
      <material name="">
        <color rgba="0.79216 0.81961 0.93333 1" />
      </material>
    </visual>
    <collision>
      <origin xyz="0 0 0" rpy="0 0 0" />
      <geometry>
        <mesh filename="${mesh_path}${mesh}" />
      </geometry>
    </collision>
  </xacro:macro>
  <xacro:macro name="visual_collision2" params="mesh">
    <visual>
      <origin xyz="0 0 0" rpy="0 0 0" />
      <geometry>
        <mesh filename="${mesh_path2}${mesh}" />
      </geometry>
      <material name="">
        <color rgba="0.79216 0.81961 0.93333 1" />
      </material>
    </visual>
    <collision>
      <origin xyz="0 0 0" rpy="0 0 0" />
      <geometry>
        <mesh filename="${mesh_path2}${mesh}" />
      </geometry>
    </collision>
  </xacro:macro>
  <link
    name="l_base_link1">
    <inertial>
      <origin
        xyz="-3.58E-05 -0.0056915 0.024464"
        rpy="0 0 0" />
      <mass
        value="0.23441" />
      <inertia
        ixx="0.00027369"
        ixy="6.5702E-08"
        ixz="2.7812E-09"
        iyy="0.000264"
        iyz="-1.6355E-06"
        izz="0.00036679" />
    </inertial>
    <xacro:visual_collision2 mesh="l_base_link1.STL" />
  </link>
  <link
    name="l_link1">
    <inertial>
      <origin
        xyz="-2.9675E-07 0.021107 -0.025188"
        rpy="0 0 0" />
      <mass
        value="0.59353" />
      <inertia
        ixx="0.0012661"
        ixy="-5.363E-09"
        ixz="-2.109E-09"
        iyy="0.0011816"
        iyz="-0.00021118"
        izz="0.00056131" />
    </inertial>
    <xacro:visual_collision mesh="l_link1.STL" />
  </link>
  <link
    name="l_link2">
    <inertial>
      <origin
        xyz="0.15226 2.3916E-07 -0.0062027"
        rpy="0 0 0" />
      <mass
        value="0.86416" />
      <inertia
        ixx="0.00063253"
        ixy="2.0103E-09"
        ixz="0.00042162"
        iyy="0.0020527"
        iyz="3.5857E-09"
        izz="0.0019528" />
    </inertial>
    <xacro:visual_collision mesh="l_link2.STL" />
  </link>
  <link
    name="l_link3">
    <inertial>
      <origin
        xyz="4.7194E-06 -0.059592 0.010268"
        rpy="0 0 0" />
      <mass
        value="0.28963" />
      <inertia
        ixx="0.00063737"
        ixy="-6.2601E-08"
        ixz="-3.5046E-08"
        iyy="0.00015649"
        iyz="-0.00014461"
        izz="0.00061418" />
    </inertial>
    <xacro:visual_collision mesh="l_link3.STL" />
  </link>
  <link
    name="l_link4">
    <inertial>
      <origin
        xyz="2.9186E-07 -0.018042 -0.02154"
        rpy="0 0 0" />
      <mass
        value="0.23942" />
      <inertia
        ixx="0.00028595"
        ixy="-2.3562E-09"
        ixz="1.3938E-09"
        iyy="0.00026273"
        iyz="4.424E-05"
        izz="0.0001199" />
    </inertial>
    <xacro:visual_collision mesh="l_link4.STL" />
  </link>
  <link
    name="l_link5">
    <inertial>
      <origin
        xyz="4.2301E-06 -0.059381 0.0070671"
        rpy="0 0 0" />
      <mass
        value="0.21879" />
      <inertia
        ixx="0.00035053"
        ixy="-2.8554E-08"
        ixz="-1.67E-08"
        iyy="0.00010492"
        iyz="-7.824E-05"
        izz="0.00033447" />
    </inertial>
    <xacro:visual_collision mesh="l_link5.STL" />
  </link>
  <link
    name="l_link6">
    <inertial>
      <origin
        xyz="0.028764 -5.1529E-06 0.025085"
        rpy="0 0 0" />
      <mass
        value="0.22147" />
      <inertia
        ixx="0.0001376"
        ixy="-5.7488E-08"
        ixz="-1.6634E-05"
        iyy="0.00026855"
        iyz="1.7799E-08"
        izz="0.00035277" />
    </inertial>
    <xacro:visual_collision mesh="l_link6.STL" />
  </link>

  <link
    name="l_link8">
    <inertial>
      <origin
        xyz="-0.0344776448483772 0.00494196667625979 -0.0105744697648362"
        rpy="0 0 0" />
      <mass
        value="0.102409228149193" />
      <inertia
        ixx="8.89659984561889E-05"
        ixy="2.51831111225342E-06"
        ixz="-1.02226936227776E-06"
        iyy="0.00010126709905583"
        iyz="7.68513067529592E-07"
        izz="3.88938021640452E-05" />
    </inertial>
    <xacro:visual_collision2 mesh="l_link8.STL" />
  </link>


    <link
    name="l_link9">
    <inertial>
      <origin
        xyz="-0.000425789891989048 -0.00198320133302361 0.0124868480183606"
        rpy="0 0 0" />
      <mass
        value="0.0314078534389695" />
      <inertia
        ixx="2.08249839281172E-05"
        ixy="9.91662953999129E-08"
        ixz="-2.07305447884078E-09"
        iyy="2.95509622657586E-06"
        iyz="3.39614376627076E-09"
        izz="2.06562510710468E-05" />
    </inertial>
    <xacro:visual_collision2 mesh="l_link9.STL" />
  </link>


  <joint
    name="l_joint1"
    type="revolute">
    <origin
      xyz="0 0 0.187"
      rpy="0 0 3.1415" />
    <parent
      link="l_base_link1" />
    <child
      link="l_link1" />
    <axis
      xyz="0 0 1" />
    <limit
      lower="-3.11"
      upper="3.11"
      effort="60"
      velocity="3.14" />
  </joint>
  <joint
    name="l_joint2"
    type="revolute">
    <origin
      xyz="0 0 0"
      rpy="1.5708 -1.5708 0" />
    <parent
      link="l_link1" />
    <child
      link="l_link2" />
    <axis
      xyz="0 0 1" />
    <limit
      lower="-2.27"
      upper="2.27"
      effort="60"
      velocity="3.14" />
  </joint>
  <joint
    name="l_joint3"
    type="revolute">
    <origin
      xyz="0.256 0 0"
      rpy="0 0 1.5708" />
    <parent
      link="l_link2" />
    <child
      link="l_link3" />
    <axis
      xyz="0 0 1" />
    <limit
      lower="-2.36"
      upper="2.36"
      effort="30"
      velocity="3.925" />
  </joint>
  <joint
    name="l_joint4"
    type="revolute">
    <origin
      xyz="0 -0.21 -0.00030007"
      rpy="1.5708 0 0" />
    <parent
      link="l_link3" />
    <child
      link="l_link4" />
    <axis
      xyz="0 0 1" />
    <limit
      lower="-3.11"
      upper="3.11"
      effort="10"
      velocity="3.925" />
  </joint>
  <joint
    name="l_joint5"
    type="revolute">
    <origin
      xyz="0 0 0"
      rpy="-1.5708 0 0" />
    <parent
      link="l_link4" />
    <child
      link="l_link5" />
    <axis
      xyz="0 0 1" />
    <limit
      lower="-2.23"
      upper="2.23"
      effort="10"
      velocity="3.925" />
  </joint>
  <joint
    name="l_joint6"
    type="revolute">
    <origin
      xyz="-0.00010528599603462 -0.1668 0.00040751929615606"            rpy="1.5707963267949 3.14 0" />
    <parent
      link="l_link5" />
    <child
      link="l_link6" />
    <axis
      xyz="0 0 1" />
    <limit
      lower="-6.28"
      upper="6.28"
      effort="10"
      velocity="3.925" />
  </joint>
    <joint
    name="l_joint7"
    type="revolute">
    <origin
      xyz="-0.0448935903863956 -0.000107308776157644 -0.0365"
      rpy="1.57079632679488 3.14 0" />
    <parent
      link="l_link6" />
    <child
      link="l_link8" />
    <axis
      xyz="0 0 -1" />
    <limit
      lower="0"
      upper="0.79"
      effort="0"
      velocity="0" />
  </joint>
   <joint
    name="l_joint8"
    type="fixed">
    <origin
      xyz="0.02800001468744 -0.0187499999999561 -0.011499999939572"
      rpy="1.5707963267949 0 1.5707963267949" />
    <parent
      link="l_link8" />
    <child
      link="l_link9" />
    <axis
      xyz="0 0 0" />
  </joint>

</robot>
